<?xml version="1.0" encoding="utf-8"?>
<!-- This URDF was automatically created by SolidWorks to URDF Exporter! Originally created by Stephen Brawner (brawner@gmail.com) 
     Commit Version: 1.6.0-4-g7f85cfe  Build Version: 1.6.7995.38578
     For more information, please see http://wiki.ros.org/sw_urdf_exporter -->
<robot
  name="y1">
  <link name="world"/>
  <joint name="fixed_base_joint" type="fixed">
    <parent link="world"/>
    <child link="base_link"/>
  </joint>
  <link
    name="base_link">
    <inertial>
      <origin
        xyz="-0.00052734 -6.0025E-06 0.026597"
        rpy="0 0 0" />
      <mass
        value="1.297" />
      <inertia
        ixx="0.0034593"
        ixy="3.9801E-08"
        ixz="-2.7609E-06"
        iyy="0.0011495"
        iyz="7.38E-08"
        izz="0.0042157" />
    </inertial>
    <visual>
      <origin
        xyz="0 0 0"
        rpy="0 0 0" />
      <geometry>
        <mesh
          filename="package://y1_description/meshes/base_link.STL" />
      </geometry>
      <material
        name="">
        <color
          rgba="0.75294 0.75294 0.75294 1" />
      </material>
    </visual>
    <collision>
      <origin
        xyz="0 0 0"
        rpy="0 0 0" />
      <geometry>
        <mesh
          filename="package://y1_description/meshes/base_link.STL" />
      </geometry>
    </collision>
  </link>
  <link
    name="J1_Link">
    <inertial>
      <origin
        xyz="3.9262E-05 -0.0010592 0.036782"
        rpy="0 0 0" />
      <mass
        value="0.34057" />
      <inertia
        ixx="0.00012062"
        ixy="5.3096E-08"
        ixz="-1.3854E-09"
        iyy="0.0001608"
        iyz="1.6367E-08"
        izz="0.00014358" />
    </inertial>
    <visual>
      <origin
        xyz="0 0 0"
        rpy="0 0 0" />
      <geometry>
        <mesh
          filename="package://y1_description/meshes/J1_Link.STL" />
      </geometry>
      <material
        name="">
        <color
          rgba="0.75294 0.75294 0.75294 1" />
      </material>
    </visual>
    <collision>
      <origin
        xyz="0 0 0"
        rpy="0 0 0" />
      <geometry>
        <mesh
          filename="package://y1_description/meshes/J1_Link.STL" />
      </geometry>
    </collision>
  </link>
  <joint
    name="J1_JOINT"
    type="revolute">
    <origin
      xyz="0 0 0.08475"
      rpy="0 0 0" />
    <parent
      link="base_link" />
    <child
      link="J1_Link" />
    <axis
      xyz="0 0 1" />
    <limit
      lower="-2.79"
      upper="2.79"
      effort="9"
      velocity="5" />
  </joint>
  <link
    name="J2_Link">
    <inertial>
      <origin
        xyz="0.14776 0.0015373 -6.263E-05"
        rpy="0 0 0" />
      <mass
        value="0.94239" />
      <inertia
        ixx="0.00033621"
        ixy="-0.00010007"
        ixz="-1.7885E-05"
        iyy="0.0067903"
        iyz="6.3442E-07"
        izz="0.0068905" />
    </inertial>
    <visual>
      <origin
        xyz="0 0 0"
        rpy="0 0 0" />
      <geometry>
        <mesh
          filename="package://y1_description/meshes/J2_Link.STL" />
      </geometry>
      <material
        name="">
        <color
          rgba="0.75294 0.75294 0.75294 1" />
      </material>
    </visual>
    <collision>
      <origin
        xyz="0 0 0"
        rpy="0 0 0" />
      <geometry>
        <mesh
          filename="package://y1_description/meshes/J2_Link.STL" />
      </geometry>
    </collision>
  </link>
  <joint
    name="J2_JOINT"
    type="revolute">
    <origin
      xyz="0 0 0.055"
      rpy="-1.5707963267949 0 0" />
    <parent
      link="J1_Link" />
    <child
      link="J2_Link" />
    <axis
      xyz="0 0 1" />
    <limit
      lower="-3.14"
      upper="0"
      effort="0"
      velocity="0" />
  </joint>
  <link
    name="J3_Link">
    <inertial>
      <origin
        xyz="-0.095861 -0.041922 0.0019274"
        rpy="0 0 0" />
      <mass
        value="0.69617" />
      <inertia
        ixx="0.00041963"
        ixy="0.00040523"
        ixz="4.3292E-06"
        iyy="0.0020271"
        iyz="-3.286E-08"
        izz="0.0022409" />
    </inertial>
    <visual>
      <origin
        xyz="0 0 0"
        rpy="0 0 0" />
      <geometry>
        <mesh
          filename="package://y1_description/meshes/J3_Link.STL" />
      </geometry>
      <material
        name="">
        <color
          rgba="0.75294 0.75294 0.75294 1" />
      </material>
    </visual>
    <collision>
      <origin
        xyz="0 0 0"
        rpy="0 0 0" />
      <geometry>
        <mesh
          filename="package://y1_description/meshes/J3_Link.STL" />
      </geometry>
    </collision>
  </link>
  <joint
    name="J3_JOINT"
    type="revolute">
    <origin
      xyz="0.28 0 0"
      rpy="0 0 0" />
    <parent
      link="J2_Link" />
    <child
      link="J3_Link" />
    <axis
      xyz="0 0 1" />
    <limit
      lower="0"
      upper="3.14"
      effort="0"
      velocity="0" />
  </joint>
  <link
    name="J4_Link">
    <inertial>
      <origin
        xyz="-0.047131 -0.039412 0.0066509"
        rpy="0 0 0" />
      <mass
        value="0.27357" />
      <inertia
        ixx="0.00015259"
        ixy="2.404E-05"
        ixz="-3.9657E-07"
        iyy="0.00013272"
        iyz="1.3905E-06"
        izz="0.00016094" />
    </inertial>
    <visual>
      <origin
        xyz="0 0 0"
        rpy="0 0 0" />
      <geometry>
        <mesh
          filename="package://y1_description/meshes/J4_Link.STL" />
      </geometry>
      <material
        name="">
        <color
          rgba="0.75294 0.75294 0.75294 1" />
      </material>
    </visual>
    <collision>
      <origin
        xyz="0 0 0"
        rpy="0 0 0" />
      <geometry>
        <mesh
          filename="package://y1_description/meshes/J4_Link.STL" />
      </geometry>
    </collision>
  </link>
  <joint
    name="J4_JOINT"
    type="revolute">
    <origin
      xyz="-0.2140106932061 -0.05098453876871 0"
      rpy="0 0 0" />
    <parent
      link="J3_Link" />
    <child
      link="J4_Link" />
    <axis
      xyz="0 0 1" />
    <limit
      lower="-1.74"
      upper="1.74"
      effort="0"
      velocity="0" />
  </joint>
  <link
    name="J5_Link">
    <inertial>
      <origin
        xyz="-0.006836 3.7476E-05 -0.027245"
        rpy="0 0 0" />
      <mass
        value="0.16994" />
      <inertia
        ixx="8.168E-05"
        ixy="3.1597E-08"
        ixz="9.4321E-06"
        iyy="6.5589E-05"
        iyz="1.5004E-08"
        izz="5.7856E-05" />
    </inertial>
    <visual>
      <origin
        xyz="0 0 0"
        rpy="0 0 0" />
      <geometry>
        <mesh
          filename="package://y1_description/meshes/J5_Link.STL" />
      </geometry>
      <material
        name="">
        <color
          rgba="0.75294 0.75294 0.75294 1" />
      </material>
    </visual>
    <collision>
      <origin
        xyz="0 0 0"
        rpy="0 0 0" />
      <geometry>
        <mesh
          filename="package://y1_description/meshes/J5_Link.STL" />
      </geometry>
    </collision>
  </link>
  <joint
    name="J5_JOINT"
    type="revolute">
    <origin
      xyz="-0.0722997230374954 -0.0454899000967161 0"
      rpy="1.5707963267949 0 0.0872664625997022" />
    <parent
      link="J4_Link" />
    <child
      link="J5_Link" />
    <axis
      xyz="0 0 -1" />
    <limit
      lower="-1.74"
      upper="1.74"
      effort="0"
      velocity="0" />
  </joint>
  <!-- <link
    name="J6_Link">
    <inertial>
      <origin
        xyz="-0.074223 0.00078642 -0.099511"
        rpy="0 0 0" />
      <mass
        value="0.8968" />
      <inertia
        ixx="0.051146"
        ixy="0.00029798"
        ixz="-0.011966"
        iyy="0.075493"
        iyz="1.8184E-05"
        izz="0.035212" />
    </inertial>
    <visual>
      <origin
        xyz="0 0 0"
        rpy="0 0 0" />
      <geometry>
        <mesh
          filename="package://y1_description/meshes/J6_Link.STL" />
      </geometry>
      <material
        name="">
        <color
          rgba="1 1 1 1" />
      </material>
    </visual>
    <collision>
      <origin
        xyz="0 0 0"
        rpy="0 0 0" />
      <geometry>
        <mesh
          filename="package://y1_description/meshes/J6_Link.STL" />
      </geometry>
    </collision>
  </link>
  <joint
    name="J6_JOINT"
    type="revolute">
    <origin
      xyz="-0.0200325738541419 0 -0.0339137808775768"
      rpy="3.14159263868863 -1.5707963267949 0" />
    <parent
      link="J5_Link" />
    <child
      link="J6_Link" />
    <axis
      xyz="0 0 -1" />
    <limit
      lower="-2.61"
      upper="2.61"
      effort="0"
      velocity="0" />
  </joint> -->
</robot>